Workbook

Sheet BOX SUMMARY 2026
A1: OLD | F1: NEW
A2: CARDBOARD | F2: CARDBOARD
A3: SIZE | B3: QTY | C3: UOM | D3: PRICE | F3: SIZE | G3: QTY | H3: UOM | I3: PRICE
A4: 7x10 | B4: 300 | C4: PCS | D4: 65 | F4: 8x8 | G4: 1500 | H4: PCS | I4: 52.5
A5: 8x8 | B5: 2000 | C5: PCS | D5: 65 | F5: 8x12 | G5: 855 | H5: PCS | I5: 73.5
A6: 8x12 | B6: 1440 | C6: PCS | D6: 115 | F6: 10x10 | G6: 995 | H6: PCS | I6: 73.5
A7: 10x10 | B7: 110 | C7: PCS | D7: 115 | F7: 10x15 | G7: 800 | H7: PCS | I7: 105
A8: 10x15 | B8: 540 | C8: PCS | D8: 130 | F8: 12x12 | G8: 997 | H8: PCS | I8: 131.25
A9: 11x11 | B9: 100 | C9: PCS | D9: 130 | F9: 12x18 | G9: 698 | H9: PCS | I9: 168
A10: 12x12 | B10: 70 | C10: PCS | D10: 130
A11: 12x18 | B11: 40 | C11: PCS | D11: 180
A12: SPECIAL | F12: SPECIAL
A13: SIZE | B13: QTY | C13: UOM | D13: PRICE | F13: SIZE | G13: QTY | H13: UOM | I13: PRICE
A14: 2x1 | B14: 366 | C14: PCS | D14: 280-380 | F14: 2x1 | G14: 300 | H14: PCS | I14: 178.5
A15: 3x1 | B15: 211 | C15: PCS | D15: 315-455 | F15: 3x1 | G15: 400 | H15: PCS | I15: 220.5
A16: 4+2 | B16: 72 | C16: PCS | D16: 630 | F16: 4x1 | G16: 250 | H16: PCS | I16: 299.25
A17: 4x1 | B17: 197 | C17: PCS | D17: 435-575 | F17: 4x1 + Carry | G17: 50 | H17: PCS | I17: 299.25
A18: 6x1 | B18: 361 | C18: PCS | D18: 605-685 | F18: 6x1 | G18: 399 | H18: PCS | I18: 393.75
A19: Big | B19: 60 | C19: PCS

Sheet 2026 - NEW
A1: SNO | B1: Combined | C1: Qty | D1: UOM | E1: PRICE | F1: CATEGORY | G1: Google Link | H1: Image | I1: Wt | J1: Design Name | K1: Dash | L1: Size | M1: TYPE | N1: PART
A2: 1 | B2: =J2&K2&L2 -> SC01-8x8 | D2: Pcs | E2: 65 | F2: CARDBOARD BOXES | G2: SC01-200G.jpeg | H2: YES | I2: 200G | J2: SC01 | K2: - | L2: 8x8 | M2: NEW | N2: 4
A3: 2 | B3: =J3&K3&L3 -> SC03-8x8 | D3: Pcs | E3: 65 | F3: CARDBOARD BOXES | G3: SC03-8x8.jpeg | H3: YES | I3: 200G | J3: SC03 | K3: - | L3: 8x8 | M3: NEW | N3: 4
A4: 3 | B4: =J4&K4&L4 -> SC06-8x8 | D4: Pcs | E4: 65 | F4: CARDBOARD BOXES | G4: SC06-8x8.jpeg | H4: YES | I4: 200G | J4: SC06 | K4: - | L4: 8x8 | M4: NEW | N4: 4
A5: 4 | B5: =J5&K5&L5 -> SC08-8x8 | D5: Pcs | E5: 65 | F5: CARDBOARD BOXES | G5: SC08-8x8.jpeg | H5: YES | I5: 200G | J5: SC08 | K5: - | L5: 8x8 | M5: NEW | N5: 4
A6: 5 | B6: =J6&K6&L6 -> SC10-8x8 | D6: Pcs | E6: 65 | F6: CARDBOARD BOXES | G6: SC10-8x8.jpeg | H6: YES | I6: 200G | J6: SC10 | K6: - | L6: 8x8 | M6: NEW | N6: 4
A7: 6 | B7: =J7&K7&L7 -> SC11-8x8 | D7: Pcs | E7: 65 | F7: CARDBOARD BOXES | G7: SC11-8x8.jpeg | H7: YES | I7: 200G | J7: SC11 | K7: - | L7: 8x8 | M7: NEW | N7: 4
A8: 7 | B8: =J8&K8&L8 -> SC04-8x12 | D8: Pcs | E8: 95 | F8: CARDBOARD BOXES | G8: SC04-8x12.jpeg | H8: YES | I8: 300G | J8: SC04 | K8: - | L8: 8x12 | M8: NEW | N8: 6
A9: 8 | B9: =J9&K9&L9 -> SC05-8x12 | D9: Pcs | E9: 95 | F9: CARDBOARD BOXES | G9: SC05-8x12.jpeg | H9: YES | I9: 300G | J9: SC05 | K9: - | L9: 8x12 | M9: NEW | N9: 6
A10: 9 | B10: =J10&K10&L10 -> SC06-8x12 | D10: Pcs | E10: 95 | F10: CARDBOARD BOXES | G10: SC06-8x12.jpeg | H10: YES | I10: 300G | J10: SC06 | K10: - | L10: 8x12 | M10: NEW | N10: 6
A11: 10 | B11: =J11&K11&L11 -> SC08-8x12 | D11: Pcs | E11: 95 | F11: CARDBOARD BOXES | G11: SC08-8x12.jpeg | H11: YES | I11: 300G | J11: SC08 | K11: - | L11: 8x12 | M11: NEW | N11: 6
A12: 11 | B12: =J12&K12&L12 -> SC09-8x12 | D12: Pcs | E12: 95 | F12: CARDBOARD BOXES | G12: SC09-8x12.jpeg | H12: YES | I12: 300G | J12: SC09 | K12: - | L12: 8x12 | M12: NEW | N12: 6
A13: 12 | B13: =J13&K13&L13 -> SC12-8x12 | D13: Pcs | E13: 95 | F13: CARDBOARD BOXES | G13: SC12-8x12.jpeg | H13: YES | I13: 300G | J13: SC12 | K13: - | L13: 8x12 | M13: NEW | N13: 6
... A42: 41 | B42: =J42&K42&L42 -> SC10-12x18 | D42: Pcs | E42: 220 | F42: CARDBOARD BOXES | G42: SC10-12x18.jpeg | H42: YES | I42: 900G | J42: SC10 | K42: - | L42: 12x18 | M42: NEW | N42: 6
A43: 42 | B43: =J43&K43&L43 -> S01-2x1 | C43: 70 | D43: Pcs | E43: 235 | F43: SPECIAL BOXES | G43: S01-2x1 | H43: YES | I43: 400G | J43: S01 | K43: - | L43: 2x1 | M43: NEW | N43: 2
A44: 43 | B44: =J44&K44&L44 -> S02-2x1 | C44: 50 | D44: Pcs | E44: 235 | F44: SPECIAL BOXES | G44: S02-2x1 | H44: YES | I44: 400G | J44: S02 | K44: - | L44: 2x1 | M44: NEW | N44: 2
A45: 44 | B45: =J45&K45&L45 -> S03-2x1 | C45: 80 | D45: Pcs | E45: 235 | F45: SPECIAL BOXES | G45: S03-2x1 | H45: YES | I45: 400G | J45: S03 | K45: - | L45: 2x1 | M45: NEW | N45: 2
A46: 45 | B46: =J46&K46&L46 -> S04-2x1 | C46: 50 | D46: Pcs | E46: 235 | F46: SPECIAL BOXES | G46: S04-2x1 | H46: YES | I46: 400G | J46: S04 | K46: - | L46: 2x1 | M46: NEW | N46: 2
A47: 46 | B47: =J47&K47&L47 -> S05-2x1 | C47: 50 | D47: Pcs | E47: 235 | F47: SPECIAL BOXES | G47: S05-2x1 | H47: YES | I47: 400G | J47: S05 | K47: - | L47: 2x1 | M47: NEW | N47: 2
A48: 47 | B48: =J48&K48&L48 -> S07-3x1 | C48: 100 | D48: Pcs | E48: 285 | F48: SPECIAL BOXES | G48: S07-3x1 | H48: YES | I48: 600G | J48: S07 | K48: - | L48: 3x1 | M48: NEW | N48: 3
A49: 48 | B49: =J49&K49&L49 -> S08-3x1 | C49: 100 | D49: Pcs | E49: 285 | F49: SPECIAL BOXES | G49: S08-3x1 | H49: YES | I49: 600G | J49: S08 | K49: - | L49: 3x1 | M49: NEW | N49: 3
A50: 49 | B50: =J50&K50&L50 -> S09-3x1 | C50: 40 | D50: Pcs | E50: 285 | F50: SPECIAL BOXES | G50: S09-3x1 | H50: YES | I50: 600G | J50: S09 | K50: - | L50: 3x1 | M50: NEW | N50: 3
A51: 50 | B51: =J51&K51&L51 -> S10-3x1 | C51: 120 | D51: Pcs | E51: 285 | F51: SPECIAL BOXES | G51: S10-3x1 | H51: YES | I51: 600G | J51: S10 | K51: - | L51: 3x1 | M51: NEW | N51: 3
A52: 51 | B52: =J52&K52&L52 -> S11-3x1 | C52: 40 | D52: Pcs | E52: 285 | F52: SPECIAL BOXES | G52: S11-3x1 | H52: YES | I52: 600G | J52: S11 | K52: - | L52: 3x1 | M52: NEW | N52: 3
A53: 52 | B53: =J53&K53&L53 -> S12-4x1 | C53: 50 | D53: Pcs | E53: 390 | F53: SPECIAL BOXES | G53: S12-4x1 | H53: YES | I53: 800G | J53: S12 | K53: - | L53: 4x1 | M53: NEW | N53: 4
A54: 53 | B54: =J54&K54&L54 -> S13-4x1 | C54: 100 | D54: Pcs | E54: 390 | F54: SPECIAL BOXES | G54: S13-4x1 | H54: YES | I54: 800G | J54: S13 | K54: - | L54: 4x1 | M54: NEW | N54: 4
... A64: 63 | B64: =J64&K64&L64 -> 264A-3x1 | C64: 24 | D64: Pcs | E64: 415 | F64: SPECIAL BOXES | G64: 264A 3 X 1.jpg | H64: YES | I64: 300 G | J64: 264A | K64: - | L64: 3x1 | M64: OLD | N64: 3
A65: 64 | B65: =J65&K65&L65 -> 2005-3x1 | C65: 12 | D65: Pcs | E65: 415 | F65: SPECIAL BOXES | I65: 300G | J65: 2005 | K65: - | L65: 3x1 | M65: OLD | N65: 3
A66: 65 | B66: =J66&K66&L66 -> 225A-3x1 | C66: 12 | D66: Pcs | E66: 555 | F66: SPECIAL BOXES | I66: 300G | J66: 225A | K66: - | L66: 3x1 | M66: OLD | N66: 3
A67: 66 | B67: =J67&K67&L67 -> 275B-3x1 | C67: 30 | D67: Pcs | E67: 555 | F67: SPECIAL BOXES | I67: 600G | J67: 275B | K67: - | L67: 3x1 | M67: OLD | N67: 3
A68: 67 | B68: =J68&K68&L68 -> 215B-3x1 | C68: 23 | D68: Pcs | E68: 555 | F68: SPECIAL BOXES | I68: 300G | J68: 215B | K68: - | L68: 3x1 | M68: OLD | N68: 3
A69: 68 | B69: =J69&K69&L69 -> 325-3x1 | C69: 24 | D69: Pcs | E69: 595 | F69: SPECIAL BOXES | I69: 450G | J69: 325 | K69: - | L69: 3x1 | M69: OLD | N69: 3
A70: 69 | B70: =J70&K70&L70 -> 335-3x1 | C70: 24 | D70: Pcs | E70: 595 | F70: SPECIAL BOXES | I70: 600G | J70: 335 | K70: - | L70: 3x1 | M70: OLD | N70: 3
A71: 70 | B71: =J71&K71&L71 -> 214A-2x1 | C71: 30 | D71: Pcs | E71: 365 | F71: SPECIAL BOXES | G71: 214A 2 X 1.png | H71: YES | I71: 400 G | J71: 214A | K71: - | L71: 2x1 | M71: OLD | N71: 2
A72: 71 | B72: =J72&K72&L72 -> 224A-2x1 | C72: 29 | D72: Pcs | E72: 365 | F72: SPECIAL BOXES | G72: 224A 2 X 1.jpg | H72: YES | I72: 400 G | J72: 224A | K72: - | L72: 2x1 | M72: OLD | N72: 2
A73: 72 | B73: =J73&K73&L73 -> 224B-2x1 | C73: 46 | D73: Pcs | E73: 365 | F73: SPECIAL BOXES | G73: 224B 2 X 1.jpg | H73: YES | I73: 400 G | J73: 224B | K73: - | L73: 2x1 | M73: OLD | N73: 2
A74: 73 | B74: =J74&K74&L74 -> 294A-2x1 | C74: 40 | D74: Pcs | E74: 365 | F74: SPECIAL BOXES | G74: 294A 2 X 1.png | H74: YES | I74: 200 G | J74: 294A | K74: - | L74: 2x1 | M74: OLD | N74: 2
A75: 74 | B75: =J75&K75&L75 -> 2005-2x1 | C75: 29 | D75: Pcs | E75: 345 | F75: SPECIAL BOXES | I75: 200G | J75: 2005 | K75: - | L75: 2x1 | M75: OLD | N75: 2
A76: 75 | B76: =J76&K76&L76 -> 2015-2x1 | C76: 21 | D76: Pcs | E76: 345 | F76: SPECIAL BOXES | I76: 200G | J76: 2015 | K76: - | L76: 2x1 | M76: OLD | N76: 2
A77: 76 | B77: =J77&K77&L77 -> 225A-2x1 | C77: 6 | D77: Pcs | E77: 490 | F77: SPECIAL BOXES | I77: 200G | J77: 225A | K77: - | L77: 2x1 | M77: OLD | N77: 2
...

Sheet RATES
A1: DRY FRUITS | B1: PRICE | C1: CATEGORY | F1: BOXES | G1: PRICE | H1: PUR | J1: PACKING | K1: PRICE
A2: KAJU | B2: 1180 | C2: REGULAR | F2: SC01-8x8 | G2: 65 | H2: 52.5 | J2: 8x8 | M2: SC01-8x8 | O2: 52.5
A3: KISHMISH GREEN | B3: 880 | C3: REGULAR | F3: SC03-8x8 | G3: 65 | H3: 52.5 | J3: 8x12 | M3: SC03-8x8 | O3: 52.5
A4: BADAM | B4: 1140 | C4: REGULAR | F4: SC06-8x8 | G4: 65 | H4: 52.5 | J4: 10x10 | M4: SC06-8x8 | O4: 52.5
A5: NAMKEEN PISTA | B5: 1880 | C5: REGULAR | F5: SC08-8x8 | G5: 65 | H5: 52.5 | J5: 11x11 | M5: SC08-8x8 | O5: 52.5
A6: KHURBANI | B6: 880 | C6: REGULAR | F6: SC10-8x8 | G6: 65 | H6: 52.5 | J6: 10x15 | M6: SC10-8x8 | O6: 52.5
A7: AKROT MAGAZ | B7: 1880 | C7: REGULAR | F7: SC11-8x8 | G7: 65 | H7: 52.5 | J7: 12x12 | M7: SC11-8x8 | O7: 52.5
A8: ANJEER | B8: 1840 | C8: REGULAR | F8: SC04-8x12 | G8: 95 | H8: 73.5 | J8: 12x18 | M8: SC04-8x12 | O8: 73.5
A9: NAMKEEN BADAM | B9: 1280 | C9: REGULAR | F9: SC05-8x12 | G9: 95 | H9: 73.5 | M9: SC05-8x12 | O9: 73.5
A10: NAMKEEN KAJU | B10: 1380 | C10: REGULAR | F10: SC06-8x12 | G10: 95 | H10: 73.5 | M10: SC06-8x12 | O10: 73.5
A11: FLAVOURED KISHMISH | B11: 1280 | C11: FLAVOURED | F11: SC08-8x12 | G11: 95 | H11: 73.5 | M11: SC08-8x12 | O11: 73.5
A12: FLAVOURED BADAM | B12: 1480 | C12: FLAVOURED | F12: SC09-8x12 | G12: 95 | H12: 73.5 | M12: SC09-8x12 | O12: 73.5
A13: FLAVOURED KAJU | B13: 1580 | C13: FLAVOURED | F13: SC12-8x12 | G13: 95 | H13: 73.5 | M13: SC12-8x12 | O13: 73.5
A14: COATED BADAM | B14: 1580 | C14: FLAVOURED | F14: SC01-10x10 | G14: 95 | H14: 73.5 | M14: SC01-10x10 | O14: 73.5
A15: COATED KISHMISH | B15: 1280 | C15: FLAVOURED | F15: SC04-10x10 | G15: 95 | H15: 73.5 | M15: SC04-10x10 | O15: 73.5
A16: BLUEBERRY | B16: 1880 | C16: BERRIES & SEEDS | F16: SC05-10x10 | G16: 95 | H16: 73.5 | M16: SC05-10x10 | O16: 73.5
A17: CRANBERRY | B17: 780 | C17: BERRIES & SEEDS | F17: SC06-10x10 | G17: 95 | H17: 73.5 | M17: SC06-10x10 | O17: 73.5
A18: MASALA CRANBERRY | B18: 940 | C18: BERRIES & SEEDS | F18: SC08-10x10 | G18: 95 | H18: 73.5 | M18: SC08-10x10 | O18: 73.5
A19: BREAKFAST MIX | B19: 1480 | C19: BERRIES & SEEDS | F19: SC09-10x10 | G19: 95 | H19: 73.5 | M19: SC09-10x10 | O19: 73.5
A20: TRAIL MIX | B20: 1480 | C20: BERRIES & SEEDS | F20: SC10-10x10 | G20: 95 | H20: 73.5 | M20: SC10-10x10 | O20: 73.5
... A31: DATE ALMONDS | B31: 1480 | C31: BITES & CHOCOLATES | F31: SC04-12x12 | G31: 170 | H31: 131.25 | M31: SC04-12x12 | O31: 131.25
F32: SC05-12x12 | G32: 170 | H32: 131.25 | M32: SC05-12x12 | O32: 131.25
F33: SC06-12x12 | G33: 170 | H33: 131.25 | M33: SC06-12x12 | O33: 131.25
F34: SC08-12x12 | G34: 170 | H34: 131.25 | M34: SC08-12x12 | O34: 131.25
F35: SC09-12x12 | G35: 170 | H35: 131.25 | M35: SC09-12x12 | O35: 131.25
F36: SC10-12x12 | G36: 170 | H36: 131.25 | M36: SC10-12x12 | O36: 131.25
F37: SC02-12x18 | G37: 220 | H37: 168 | M37: SC02-12x18 | O37: 168
F38: SC04-12x18 | G38: 220 | H38: 168 | M38: SC04-12x18 | O38: 168
F39: SC05-12x18 | G39: 220 | H39: 168 | M39: SC05-12x18 | O39: 168
F40: SC06-12x18 | G40: 220 | H40: 168 | M40: SC06-12x18 | O40: 168
F41: SC08-12x18 | G41: 220 | H41: 168 | M41: SC08-12x18 | O41: 168
F42: SC10-12x18 | G42: 220 | H42: 168 | M42: SC10-12x18 | O42: 168
F43: S01-2x1 | G43: 235 | H43: 178.5 | M43: S01-2x1 | O43: 178.5
... F113: 404-10x15 | G113: 155 | H113: 120 | M113: 404-10x15 | O113: 120
F114: 1373A-Big | G114: 1150 | H114: 900 | M114: 1373A-Big
F115: 1225-4+2 | G115: 820 | H115: 630 | M115: 1225-4+2 | O115: 630
F116: 1205-4+2 | G116: 820 | H116: 630 | M116: 1205-4+2 | O116: 630
F117: 1215-4+2 | G117: 820 | H117: 630 | M117: 1215-4+2 | O117: 630
F118: MN19-10x10 | G118: 145 | H118: 110 | M118: MN19-10x10 | O118: 110
F119: MN20-10x10 | G119: 145 | H119: 110 | M119: MN20-10x10 | O119: 110
...

Sheet CALC
A1: 2x1 | G1: 3x1 - AJAY BHAII
A3: SNO | B3: PARTICULARS | C3: QTY | D3: RATE | E3: GROSS | G3: SNO | H3: PARTICULARS | I3: QTY | J3: RATE | K3: GROSS
A4: 1 | B4: KAJU | C4: 0.2 | D4: =VLOOKUP(B4,RATES!$A$1:$B$116,2,0) -> 1180 | E4: =C4*D4 -> 236 | G4: 1 | H4: FLAVOURED KAJU | I4: 0.2 | J4: 1180 | K4: =I4*J4 -> 236
A5: 2 | B5: BADAM | C5: 0.2 | D5: =VLOOKUP(B5,RATES!$A$1:$B$116,2,0) -> 1140 | E5: =C5*D5 -> 228 | G5: 2 | H5: FLAVOURED BADAM | I5: 0.2 | J5: =VLOOKUP(H5,RATES!$A$1:$B$116,2,0) -> 1480 | K5: =I5*J5 -> 296
A6: 3 | B6: 024-2x1 | C6: 1 | D6: =vlookup(B6,RATES!$F$1:$G$164,2,0) -> 495 | E6: =C6*D6 -> 495 | G6: 3 | H6: CRUNCHIES | I6: 0.2 | J6: =VLOOKUP(H6,RATES!$A$1:$B$116,2,0) -> 1480 | K6: =I6*J6 -> 296
A7: 4 | B7: PACKING CHARGES | C7: 1 | D7: 50 | E7: =C7*D7 -> 50 | G7: 4 | H7: 2015-3x1 | I7: 1 | J7: =vlookup(H7,RATES!$F$1:$G$164,2,0) -> #N/A | K7: =I7*J7 -> #N/A
A8: TOTAL | E8: =SUM(E4:E7) -> 1009 | G8: 5 | H8: PACKING CHARGES | I8: 1 | J8: 40 | K8: =I8*J8 -> 40
G9: TOTAL | K9: =SUM(K4:K8) -> #N/A
A13: 4x1 | G13: 6x1
A15: SNO | B15: PARTICULARS | C15: QTY | D15: RATE | E15: GROSS | G15: SNO | H15: PARTICULARS | I15: QTY | J15: RATE | K15: GROSS
A16: 1 | B16: PREMIUM NAMKEEN PISTA | C16: 0.2 | D16: =VLOOKUP(B16,RATES!$A$1:$B$116,2,0) -> #N/A | E16: =C16*D16 -> #N/A | G16: 1 | H16: MASALA CRANBERRY | I16: 0.2 | J16: 880 | K16: =I16*J16 -> 176
A17: 2 | B17: FLAVOURED KAJU | C17: 0.2 | D17: =VLOOKUP(B17,RATES!$A$1:$B$116,2,0) -> 1580 | E17: =C17*D17 -> 316 | G17: 2 | H17: FLAVOURED BADAM | I17: 0.2 | J17: 1580 | K17: =I17*J17 -> 316
A18: 3 | B18: FLAVOURED BADAM | C18: 0.2 | D18: =VLOOKUP(B18,RATES!$A$1:$B$116,2,0) -> 1480 | E18: =C18*D18 -> 296 | G18: 3 | H18: FLAVOURED KAJU | I18: 0.2 | J18: 1680 | K18: =I18*J18 -> 336
A19: 4 | B19: MASALA CRANBERRY | C19: 0.2 | D19: =VLOOKUP(B19,RATES!$A$1:$B$116,2,0) -> 940 | E19: =C19*D19 -> 188 | G19: 4 | H19: BREAKFAST MIX | I19: 0.2 | J19: 1280 | K19: =I19*J19 -> 256
A20: 5 | B20: 7037-Triangle Bag | C20: 1 | D20: =vlookup(B20,RATES!$F$1:$G$164,2,0) -> #N/A | E20: =C20*D20 -> #N/A | G20: 5 | H20: FLAVOURED PISTA | I20: 0.2 | J20: 1580 | K20: =I20*J20 -> 316
A21: 6 | B21: PACKING CHARGES | C21: 1 | D21: 50 | E21: =C21*D21 -> 50 | G21: 6 | H21: DATE ALMONDS | I21: 0.2 | J21: 1480 | K21: =I21*J21 -> 296
A22: TOTAL | E22: =SUM(E16:E21) -> #N/A | G22: 7 | H22: 025-6x1 | I22: 1 | J22: =vlookup(H22,RATES!$F$1:$G$164,2,0) -> 820 | K22: =I22*J22 -> 820
G23: 8 | H23: PACKING CHARGES | I23: 1 | J23: 50 | K23: =I23*J23 -> 50
G24: TOTAL | K24: =SUM(K16:K23) -> 2566
A27: 8x1
A29: SNO | B29: PARTICULARS | C29: QTY | D29: RATE | E29: GROSS
A30: 1 | B30: AKROT MAGAZ | C30: 0.05 | D30: =VLOOKUP(B30,RATES!$A$1:$B$116,2,0) -> 1880 | E30: =C30*D30 -> 94
A31: 2 | B31: ANJEER | C31: 0.05 | D31: =VLOOKUP(B31,RATES!$A$1:$B$116,2,0) -> 1840 | E31: =C31*D31 -> 92
A32: 3 | B32: BADAM | C32: 0.05 | D32: =VLOOKUP(B32,RATES!$A$1:$B$116,2,0) -> 1140 | E32: =C32*D32 -> 57
A33: 4 | B33: BUBBLE GUM KISHMISH | C33: 0.05 | D33: =VLOOKUP(B33,RATES!$A$1:$B$116,2,0) -> #N/A | E33: =C33*D33 -> #N/A
A34: 5 | B34: MAMRA BADAM | C34: 0.05 | D34: =VLOOKUP(B34,RATES!$A$1:$B$116,2,0) -> #N/A | E34: =C34*D34 -> #N/A
A35: 6 | B35: ANJEER | C35: 0.05 | D35: =VLOOKUP(B35,RATES!$A$1:$B$116,2,0) -> 1840 | E35: =C35*D35 -> 92
A36: 7 | B36: BARBEQUE KAJU | C36: 0.05 | D36: =VLOOKUP(B36,RATES!$A$1:$B$116,2,0) -> #N/A | E36: =C36*D36 -> #N/A
A37: 8 | B37: MASALA CRANBERRY | C37: 0.05 | D37: =VLOOKUP(B37,RATES!$A$1:$B$116,2,0) -> 940 | E37: =C37*D37 -> 47
A38: 9 | B38: 025F-8x8 | C38: 1 | D38: =vlookup(B38,RATES!$F$1:$G$164,2,0) -> #N/A | E38: =C38*D38 -> #N/A
A39: 10 | B39: PACKING CHARGES | C39: 1 | D39: 65 | E39: =C39*D39 -> 65
A40: TOTAL | E40: =SUM(E30:E39) -> #N/A

Sheet 2025
B1: Combined | C1: Qty | D1: UOM | E1: PUR | F1: CATEGORY | G1: Google Link | H1: Image | I1: Wt | J1: Design Name | K1: Dash | L1: Size | M1: TYPE | N1: TH YR
A2: 51 | B2: =J2&K2&L2 -> 2005-3x1 | C2: =VLOOKUP(B2,Stock!$B$2:$C$193,2,0) -> 30 | D2: Pcs | E2: =VLOOKUP(B2,RATES!$F$1:$G$152,2,0) -> 415 | F2: SPECIAL BOXES | I2: 300G | J2: 2005 | K2: - | L2: 3x1 | M2: NEW | N2: 1
A3: 57 | B3: =J3&K3&L3 -> 225A-3x1 | C3: =VLOOKUP(B3,Stock!$B$2:$C$193,2,0) -> 30 | D3: Pcs | E3: =VLOOKUP(B3,RATES!$F$1:$G$152,2,0) -> 555 | F3: SPECIAL BOXES | I3: 300G | J3: 225A | K3: - | L3: 3x1 | M3: NEW | N3: 1
A4: 65 | B4: =J4&K4&L4 -> 275B-3x1 | C4: =VLOOKUP(B4,Stock!$B$2:$C$193,2,0) -> 30 | D4: Pcs | E4: =VLOOKUP(B4,RATES!$F$1:$G$152,2,0) -> 555 | F4: SPECIAL BOXES | I4: 600G | J4: 275B | K4: - | L4: 3x1 | M4: NEW | N4: 1
A5: 77 | B5: =J5&K5&L5 -> 215B-3x1 | C5: =VLOOKUP(B5,Stock!$B$2:$C$193,2,0) -> 30 | D5: Pcs | E5: =VLOOKUP(B5,RATES!$F$1:$G$152,2,0) -> 555 | F5: SPECIAL BOXES | I5: 300G | J5: 215B | K5: - | L5: 3x1 | M5: NEW | N5: 1
A6: 102 | B6: =J6&K6&L6 -> 325-3x1 | C6: =VLOOKUP(B6,Stock!$B$2:$C$193,2,0) -> 30 | D6: Pcs | E6: =VLOOKUP(B6,RATES!$F$1:$G$152,2,0) -> 595 | F6: SPECIAL BOXES | I6: 450G | J6: 325 | K6: - | L6: 3x1 | M6: NEW | N6: 1
A7: 105 | B7: =J7&K7&L7 -> 335-3x1 | C7: =VLOOKUP(B7,Stock!$B$2:$C$193,2,0) -> 30 | D7: Pcs | E7: =VLOOKUP(B7,RATES!$F$1:$G$152,2,0) -> 595 | F7: SPECIAL BOXES | I7: 600G | J7: 335 | K7: - | L7: 3x1 | M7: NEW | N7: 1
A8: 1 | B8: =J8&K8&L8 -> 025D-8x8 | C8: =VLOOKUP(B8,Stock!$B$2:$C$193,2,0) -> 250 | D8: Pcs | E8: =VLOOKUP(B8,RATES!$F$1:$G$152,2,0) -> #N/A | F8: CARDBOARD BOXES | I8: 200G | J8: 025D | K8: - | L8: 8x8 | M8: NEW
A9: 2 | B9: =J9&K9&L9 -> 025A-8x8 | C9: =VLOOKUP(B9,Stock!$B$2:$C$193,2,0) -> 250 | D9: Pcs | E9: =VLOOKUP(B9,RATES!$F$1:$G$152,2,0) -> #N/A | F9: CARDBOARD BOXES | I9: 200G | J9: 025A | K9: - | L9: 8x8 | M9: NEW
A10: 3 | B10: =J10&K10&L10 -> 025I-8x8 | C10: =VLOOKUP(B10,Stock!$B$2:$C$193,2,0) -> 250 | D10: Pcs | E10: =VLOOKUP(B10,RATES!$F$1:$G$152,2,0) -> #N/A | F10: CARDBOARD BOXES | I10: 200G | J10: 025I | K10: - | L10: 8x8 | M10: NEW
A11: 4 | B11: =J11&K11&L11 -> 025E-8x8 | C11: =VLOOKUP(B11,Stock!$B$2:$C$193,2,0) -> 250 | D11: Pcs | E11: =VLOOKUP(B11,RATES!$F$1:$G$152,2,0) -> #N/A | F11: CARDBOARD BOXES | I11: 200G | J11: 025E | K11: - | L11: 8x8 | M11: NEW
A12: 5 | B12: =J12&K12&L12 -> 025C-8x8 | C12: =VLOOKUP(B12,Stock!$B$2:$C$193,2,0) -> 250 | D12: Pcs | E12: =VLOOKUP(B12,RATES!$F$1:$G$152,2,0) -> #N/A | F12: CARDBOARD BOXES | I12: 200G | J12: 025C | K12: - | L12: 8x8 | M12: NEW
A13: 6 | B13: =J13&K13&L13 -> 025H-8x8 | C13: =VLOOKUP(B13,Stock!$B$2:$C$193,2,0) -> 250 | D13: Pcs | E13: =VLOOKUP(B13,RATES!$F$1:$G$152,2,0) -> #N/A | F13: CARDBOARD BOXES | I13: 200G | J13: 025H | K13: - | L13: 8x8 | M13: NEW
A14: 7 | B14: =J14&K14&L14 -> 025F-8x8 | C14: =VLOOKUP(B14,Stock!$B$2:$C$193,2,0) -> 250 | D14: Pcs | E14: =VLOOKUP(B14,RATES!$F$1:$G$152,2,0) -> #N/A | F14: CARDBOARD BOXES | I14: 200G | J14: 025F | K14: - | L14: 8x8 | M14: NEW
A15: 8 | B15: =J15&K15&L15 -> 025B-8x8 | C15: =VLOOKUP(B15,Stock!$B$2:$C$193,2,0) -> 250 | D15: Pcs | E15: =VLOOKUP(B15,RATES!$F$1:$G$152,2,0) -> #N/A | F15: CARDBOARD BOXES | I15: 200G | J15: 025B | K15: - | L15: 8x8 | M15: NEW
A16: 9 | B16: =J16&K16&L16 -> 1035-10x10 | C16: =VLOOKUP(B16,Stock!$B$2:$C$193,2,0) -> 200 | D16: Pcs | E16: =VLOOKUP(B16,RATES!$F$1:$G$152,2,0) -> #N/A | F16: CARDBOARD BOXES | I16: 400G | J16: 1035 | K16: - | L16: 10x10 | M16: NEW
A17: 10 | B17: =J17&K17&L17 -> 1085-10x10 | C17: =VLOOKUP(B17,Stock!$B$2:$C$193,2,0) -> 200 | D17: Pcs | E17: =VLOOKUP(B17,RATES!$F$1:$G$152,2,0) -> #N/A | F17: CARDBOARD BOXES | I17: 400G | J17: 1085 | K17: - | L17: 10x10 | M17: NEW
A18: 11 | B18: =J18&K18&L18 -> 1015-10x10 | C18: =VLOOKUP(B18,Stock!$B$2:$C$193,2,0) -> 200 | D18: Pcs | E18: =VLOOKUP(B18,RATES!$F$1:$G$152,2,0) -> #N/A | F18: CARDBOARD BOXES | I18: 400G | J18: 1015 | K18: - | L18: 10x10 | M18: NEW
A19: 12 | B19: =J19&K19&L19 -> 1055-10x10 | C19: =VLOOKUP(B19,Stock!$B$2:$C$193,2,0) -> 200 | D19: Pcs | E19: =VLOOKUP(B19,RATES!$F$1:$G$152,2,0) -> #N/A | F19: CARDBOARD BOXES | I19: 400G | J19: 1055 | K19: - | L19: 10x10 | M19: NEW
... A56: 49 | B56: =J56&K56&L56 -> 1185-12x18 | C56: =VLOOKUP(B56,Stock!$B$2:$C$193,2,0) -> 150 | D56: Pcs | E56: =VLOOKUP(B56,RATES!$F$1:$G$152,2,0) -> #N/A | F56: CARDBOARD BOXES | I56: 900G | J56: 1185 | K56: - | L56: 12x18 | M56: NEW
A57: 50 | B57: =J57&K57&L57 -> 2005-2x1 | C57: =VLOOKUP(B57,Stock!$B$2:$C$193,2,0) -> 30 | D57: Pcs | E57: =VLOOKUP(B57,RATES!$F$1:$G$152,2,0) -> 345 | F57: SPECIAL BOXES | I57: 200G | J57: 2005 | K57: - | L57: 2x1 | M57: NEW | N57: 1
A58: 52 | B58: =J58&K58&L58 -> 2005-4x1 | C58: =VLOOKUP(B58,Stock!$B$2:$C$193,2,0) -> 30 | D58: Pcs | E58: =VLOOKUP(B58,RATES!$F$1:$G$152,2,0) -> 570 | F58: SPECIAL BOXES | I58: 400G | J58: 2005 | K58: - | L58: 4x1 | M58: NEW | N58: 1
A59: 53 | B59: =J59&K59&L59 -> 2015-2x1 | C59: =VLOOKUP(B59,Stock!$B$2:$C$193,2,0) -> 30 | D59: Pcs | E59: =VLOOKUP(B59,RATES!$F$1:$G$152,2,0) -> 345 | F59: SPECIAL BOXES | I59: 200G | J59: 2015 | K59: - | L59: 2x1 | M59: NEW | N59: 1
A60: 54 | B60: =J60&K60&L60 -> 2015-3x1 | C60: =VLOOKUP(B60,Stock!$B$2:$C$193,2,0) -> 30 | D60: Pcs | E60: =VLOOKUP(B60,RATES!$F$1:$G$152,2,0) -> #N/A | F60: SPECIAL BOXES | I60: 300G | J60: 2015 | K60: - | L60: 3x1 | M60: NEW
A61: 62 | B61: =J61&K61&L61 -> 235B-4x1 | C61: =VLOOKUP(B61,Stock!$B$2:$C$193,2,0) -> 30 | D61: Pcs | E61: =VLOOKUP(B61,RATES!$F$1:$G$152,2,0) -> 675 | F61: SPECIAL BOXES | I61: 600G | J61: 235B | K61: - | L61: 4x1 | M61: NEW | N61: 1
A62: 56 | B62: =J62&K62&L62 -> 225A-2x1 | C62: =VLOOKUP(B62,Stock!$B$2:$C$193,2,0) -> 30 | D62: Pcs | E62: =VLOOKUP(B62,RATES!$F$1:$G$152,2,0) -> 490 | F62: SPECIAL BOXES | I62: 200G | J62: 225A | K62: - | L62: 2x1 | M62: NEW | N62: 1
A63: 78 | B63: =J63&K63&L63 -> 215B-4x1 | C63: =VLOOKUP(B63,Stock!$B$2:$C$193,2,0) -> 30 | D63: Pcs | E63: =VLOOKUP(B63,RATES!$F$1:$G$152,2,0) -> 675 | F63: SPECIAL BOXES | I63: 400G | J63: 215B | K63: - | L63: 4x1 | M63: NEW | N63: 1
A64: 63 | B64: =J64&K64&L64 -> 235B-6x1 | C64: =VLOOKUP(B64,Stock!$B$2:$C$193,2,0) -> 30 | D64: Pcs | E64: =VLOOKUP(B64,RATES!$F$1:$G$152,2,0) -> 820 | F64: SPECIAL BOXES | I64: 900G | J64: 235B | K64: - | L64: 6x1 | M64: NEW | N64: 1
A65: 60 | B65: =J65&K65&L65 -> 235B-2x1 | C65: =VLOOKUP(B65,Stock!$B$2:$C$193,2,0) -> 30 | D65: Pcs | E65: =VLOOKUP(B65,RATES!$F$1:$G$152,2,0) -> 495 | F65: SPECIAL BOXES | I65: 300G | J65: 235B | K65: - | L65: 2x1 | M65: NEW | N65: 1
A66: 61 | B66: =J66&K66&L66 -> 235B-3x1 | C66: =VLOOKUP(B66,Stock!$B$2:$C$193,2,0) -> 30 | D66: Pcs | E66: =VLOOKUP(B66,RATES!$F$1:$G$152,2,0) -> #N/A | F66: SPECIAL BOXES | I66: 450G | J66: 235B | K66: - | L66: 3x1 | M66: NEW
A67: 82 | B67: =J67&K67&L67 -> 235A-4x1 | C67: =VLOOKUP(B67,Stock!$B$2:$C$193,2,0) -> 30 | D67: Pcs | E67: =VLOOKUP(B67,RATES!$F$1:$G$152,2,0) -> 675 | F67: SPECIAL BOXES | I67: 600G | J67: 235A | K67: - | L67: 4x1 | M67: NEW | N67: 1
A68: 79 | B68: =J68&K68&L68 -> 215B-6x1 | C68: =VLOOKUP(B68,Stock!$B$2:$C$193,2,0) -> 30 | D68: Pcs | E68: =VLOOKUP(B68,RATES!$F$1:$G$152,2,0) -> 820 | F68: SPECIAL BOXES | I68: 600G | J68: 215B | K68: - | L68: 6x1 | M68: NEW | N68: 1
A69: 64 | B69: =J69&K69&L69 -> 275B-2x1 | C69: =VLOOKUP(B69,Stock!$B$2:$C$193,2,0) -> 30 | D69: Pcs | E69: =VLOOKUP(B69,RATES!$F$1:$G$152,2,0) -> 495 | F69: SPECIAL BOXES | I69: 400G | J69: 275B | K69: - | L69: 2x1 | M69: NEW | N69: 1
A70: 108 | B70: =J70&K70&L70 -> 7005-4x1 | C70: =VLOOKUP(B70,Stock!$B$2:$C$193,2,0) -> 50 | D70: Pcs | E70: =VLOOKUP(B70,RATES!$F$1:$G$152,2,0) -> 750 | F70: SPECIAL BOXES | I70: 200G | J70: 7005 | K70: - | L70: 4x1 | M70: NEW | N70: 1
A71: 83 | B71: =J71&K71&L71 -> 235A-6x1 | C71: =VLOOKUP(B71,Stock!$B$2:$C$193,2,0) -> 30 | D71: Pcs | E71: =VLOOKUP(B71,RATES!$F$1:$G$152,2,0) -> 820 | F71: SPECIAL BOXES | I71: 900G | J71: 235A | K71: - | L71: 6x1 | M71: NEW | N71: 1
A72: 68 | B72: =J72&K72&L72 -> 245B-2x1 | C72: =VLOOKUP(B72,Stock!$B$2:$C$193,2,0) -> 30 | D72: Pcs | E72: =VLOOKUP(B72,RATES!$F$1:$G$152,2,0) -> 495 | F72: SPECIAL BOXES | I72: 300G | J72: 245B | K72: - | L72: 2x1 | M72: NEW | N72: 1
A73: 69 | B73: =J73&K73&L73 -> 245B-3x1 | C73: =VLOOKUP(B73,Stock!$B$2:$C$193,2,0) -> 30 | D73: Pcs | E73: =VLOOKUP(B73,RATES!$F$1:$G$152,2,0) -> #N/A | F73: SPECIAL BOXES | I73: 450G | J73: 245B | K73: - | L73: 3x1 | M73: NEW
A74: 110 | B74: =J74&K74&L74 -> 7004-4x1 | C74: =VLOOKUP(B74,Stock!$B$2:$C$193,2,0) -> 50 | D74: Pcs | E74: =VLOOKUP(B74,RATES!$F$1:$G$152,2,0) -> 750 | F74: SPECIAL BOXES | I74: 600G | J74: 7004 | K74: - | L74: 4x1 | M74: NEW | N74: 1
A75: 99 | B75: =J75&K75&L75 -> 205B-6x1 | C75: =VLOOKUP(B75,Stock!$B$2:$C$193,2,0) -> 60 | D75: Pcs | E75: =VLOOKUP(B75,RATES!$F$1:$G$152,2,0) -> 820 | F75: SPECIAL BOXES | I75: 600G | J75: 205B | K75: - | L75: 6x1 | M75: NEW | N75: 1
A76: 72 | B76: =J76&K76&L76 -> 265B-2x1 | C76: =VLOOKUP(B76,Stock!$B$2:$C$193,2,0) -> 30 | D76: Pcs | E76: =VLOOKUP(B76,RATES!$F$1:$G$152,2,0) -> 495 | F76: SPECIAL BOXES | I76: 400G | J76: 265B | K76: - | L76: 2x1 | M76: NEW | N76: 1
...

Sheet 2024
A1: Combined | B1: Qty | C1: UOM | D1: PUR | E1: CATEGORY | F1: Google Link | G1: Wt | H1: this yr
A2: 214A-3x1 | C2: Pcs | D2: 320 | E2: SPECIAL BOXES | F2: 214A 3 X 1.png | G2: 600 G | H2: 1
A3: 224A-3x1 | C3: Pcs | D3: 320 | E3: SPECIAL BOXES | F3: 224A 3 X 1.jpg | G3: 600 G | H3: 1
A4: 224B-3x1 | C4: Pcs | D4: 320 | E4: SPECIAL BOXES | F4: 224B 3 X 1.jpg | G4: 600 G | H4: 1
A5: 264A-3x1 | C5: Pcs | D5: 320 | E5: SPECIAL BOXES | F5: 264A 3 X 1.jpg | G5: 300 G | H5: 1
A6: - | B6: #N/A | C6: Pcs
A7: 024A-8x8 | C7: Pcs | D7: 48 | E7: CARDBOARD BOXES | F7: 024.A 8 X 8.png | G7: 200 G
A8: 024B-8x8 | C8: Pcs | D8: 48 | E8: CARDBOARD BOXES | F8: 024B 8X8.png | G8: 200 G
A9: 024C-8x8 | C9: Pcs | D9: 48 | E9: CARDBOARD BOXES | F9: 024C 8 X 8.png | G9: 200 G
A10: 024D-8x8 | C10: Pcs | D10: 48 | E10: CARDBOARD BOXES | F10: 024D 8 X 8.png | G10: 200 G
A11: 029-4x1 | C11: Pcs | D11: 450 | E11: SPECIAL BOXES | F11: 029 jute 4 x 1.jpg
A12: 029-6x1 | C12: Pcs | D12: 550 | E12: SPECIAL BOXES | F12: 029 jute 6 x 1.jpg
A13: 034A-7x10 | C13: Pcs | D13: 48 | E13: CARDBOARD BOXES | F13: 034.A 7X10.png | G13: 200 G
A14: 034B-7x10 | C14: Pcs | D14: 48 | E14: CARDBOARD BOXES | F14: 034.B 7X10.png | G14: 200 G
A15: 034C-7x10 | C15: Pcs | D15: 48 | E15: CARDBOARD BOXES | F15: 034 C 7 X10.png | G15: 200 G
A16: 034D-7x10 | C16: Pcs | D16: 48 | E16: CARDBOARD BOXES | F16: 034.D 7X10.png | G16: 200 G
A17: 1004-10x10 | C17: Pcs | D17: 83 | E17: CARDBOARD BOXES | F17: 1004 10 X 10.png | G17: 400 G
A18: 101-8 X 12 | B18: #N/A | C18: Pcs | E18: CARDBOARD BOXES | F18: 101 8x12.jpeg
A19: 1014-10x10 | C19: Pcs | D19: 83 | E19: CARDBOARD BOXES | F19: 1014 10 X 10.png | G19: 400 G
A20: 1014-12x12 | C20: Pcs | D20: 93 | E20: CARDBOARD BOXES | F20: 1014 12 X12.png | G20: 800 G
A21: 1024-10x10 | C21: Pcs | D21: 83 | E21: CARDBOARD BOXES | F21: 1024 10 X 10.png | G21: 400 G
A22: 1024-12x12 | C22: Pcs | D22: 93 | E22: CARDBOARD BOXES | F22: 1024 12 X 12.png | G22: 800 G
A23: 103-11 X 11 | B23: #N/A | C23: Pcs | E23: CARDBOARD BOXES | F23: 103 11 X 11 40 G.jpg
A24: 103-12 X 18. | B24: #N/A | C24: Pcs | E24: CARDBOARD BOXES | F24: 103 12X18.jpeg
A25: 1034-10x10 | C25: Pcs | D25: 83 | E25: CARDBOARD BOXES | F25: 1034 10 X10.png | G25: 400 G
A26: 1034-12x12 | C26: Pcs | D26: 93 | E26: CARDBOARD BOXES | F26: 1034 12 X 12.png | G26: 800 G
A27: 1044-10x10 | C27: Pcs | D27: 83 | E27: CARDBOARD BOXES | F27: 1044 10 X10.png | G27: 400 G
A28: 1044-12x12 | C28: Pcs | D28: 93 | E28: CARDBOARD BOXES | F28: 1044 12 X12.png | G28: 800 G
A29: 1054-10x10 | C29: Pcs | D29: 83 | E29: CARDBOARD BOXES | F29: 1054 10 X10.png | G29: 400 G
A30: 1104-10x15 | C30: Pcs | D30: 93 | E30: CARDBOARD BOXES | F30: 1104 10 X 15.png | G30: 600 G
A31: 1104-12x18 | C31: Pcs | D31: 130 | E31: CARDBOARD BOXES | F31: 1104 12 X 18.png | G31: 900 G
A32: 1104-8x12 | C32: Pcs | D32: 83 | E32: CARDBOARD BOXES | F32: 1104 8 X 12.png | G32: 300 G
A33: 1114-10x15 | C33: Pcs | D33: 93 | E33: CARDBOARD BOXES | F33: 1114 10 X 15.png | G33: 600 G
A34: 1114-12x18 | C34: Pcs | D34: 130 | E34: CARDBOARD BOXES | F34: 1114 12 X 18.png | G34: 900 G
A35: 1114-8x12 | C35: Pcs | D35: 83 | E35: CARDBOARD BOXES | F35: 1114 8 X12.png | G35: 300 G
A36: 111A-8 X 12 | B36: #N/A | C36: Pcs | E36: CARDBOARD BOXES | F36: 111 A 8x12.jpeg
A37: 111B-8 X 12 | B37: #N/A | C37: Pcs | E37: CARDBOARD BOXES | F37: 111 B 8x12.jpeg
A38: 1124-10x15 | C38: Pcs | D38: 93 | E38: CARDBOARD BOXES | F38: 1124 10 X 15.png | G38: 600 G
A39: 1124-12x18 | C39: Pcs | D39: 130 | E39: CARDBOARD BOXES | F39: 1124 12 X 18.png | G39: 900 G
A40: 1124-8x12 | C40: Pcs | D40: 83 | E40: CARDBOARD BOXES | F40: 1124 8 X 12.png | G40: 300 G
...

Sheet Stock
A1: STOCK - DIWALI BOXES
A2: CODE | B2: Product Name | C2: Qty | D2: Reminder | E2: MBQ | F2: Ex Stock | G2: Case | H2: Pcs
A3: 3 | B3: Item C | C3: =50 + SUMIF(Purchase!C:C,Stock!B3,Purchase!D:D)-SUMIF(Sale!C:C,Stock!B3,Sale!D:D) -> 50 | D3: =IF(C3<E3,"Low Stock","In Stock") -> In Stock | E3: 1 | F3: 0 | G3: 0 | H3: =G3*C3 -> 0
D4: =IF(C4<E4,"Low Stock","In Stock") -> Low Stock | E4: 1 | F4: 0 | G4: 0 | H4: =G4*C4 -> 0
A5: 025D-8x8 | B5: 025D-8x8 | C5: =F5 + SUMIF(Purchase!C:C,Stock!B5,Purchase!D:D)-SUMIF(Sale!C:C,Stock!B5,Sale!D:D) -> 250 | D5: =IF(C5<E5,"Low Stock","In Stock") -> In Stock | E5: 1 | F5: 250 | G5: 0 | H5: =G5*C5 -> 0
A6: 025A-8x8 | B6: 025A-8x8 | C6: =F6 + SUMIF(Purchase!C:C,Stock!B6,Purchase!D:D)-SUMIF(Sale!C:C,Stock!B6,Sale!D:D) -> 250 | D6: =IF(C6<E6,"Low Stock","In Stock") -> In Stock | E6: 1 | F6: 250 | G6: 0 | H6: =G6*C6 -> 0
A7: 025I-8x8 | B7: 025I-8x8 | C7: =F7 + SUMIF(Purchase!C:C,Stock!B7,Purchase!D:D)-SUMIF(Sale!C:C,Stock!B7,Sale!D:D) -> 250 | D7: =IF(C7<E7,"Low Stock","In Stock") -> In Stock | E7: 1 | F7: 250 | G7: 0 | H7: =G7*C7 -> 0
A8: 025E-8x8 | B8: 025E-8x8 | C8: =F8 + SUMIF(Purchase!C:C,Stock!B8,Purchase!D:D)-SUMIF(Sale!C:C,Stock!B8,Sale!D:D) -> 250 | D8: =IF(C8<E8,"Low Stock","In Stock") -> In Stock | E8: 1 | F8: 250 | G8: 0 | H8: =G8*C8 -> 0
A9: 025C-8x8 | B9: 025C-8x8 | C9: =F9 + SUMIF(Purchase!C:C,Stock!B9,Purchase!D:D)-SUMIF(Sale!C:C,Stock!B9,Sale!D:D) -> 250 | D9: =IF(C9<E9,"Low Stock","In Stock") -> In Stock | E9: 1 | F9: 250 | G9: 0 | H9: =G9*C9 -> 0
A10: 025H-8x8 | B10: 025H-8x8 | C10: =F10 + SUMIF(Purchase!C:C,Stock!B10,Purchase!D:D)-SUMIF(Sale!C:C,Stock!B10,Sale!D:D) -> 250 | D10: =IF(C10<E10,"Low Stock","In Stock") -> In Stock | E10: 1 | F10: 250 | G10: 0 | H10: =G10*C10 -> 0
A11: 025F-8x8 | B11: 025F-8x8 | C11: =F11 + SUMIF(Purchase!C:C,Stock!B11,Purchase!D:D)-SUMIF(Sale!C:C,Stock!B11,Sale!D:D) -> 250 | D11: =IF(C11<E11,"Low Stock","In Stock") -> In Stock | E11: 1 | F11: 250 | G11: 0 | H11: =G11*C11 -> 0
A12: 025B-8x8 | B12: 025B-8x8 | C12: =F12 + SUMIF(Purchase!C:C,Stock!B12,Purchase!D:D)-SUMIF(Sale!C:C,Stock!B12,Sale!D:D) -> 250 | D12: =IF(C12<E12,"Low Stock","In Stock") -> In Stock | E12: 1 | F12: 250 | G12: 0 | H12: =G12*C12 -> 0
A13: 1035-10x10 | B13: 1035-10x10 | C13: =F13 + SUMIF(Purchase!C:C,Stock!B13,Purchase!D:D)-SUMIF(Sale!C:C,Stock!B13,Sale!D:D) -> 200 | D13: =IF(C13<E13,"Low Stock","In Stock") -> In Stock | E13: 1 | F13: 200 | G13: 0 | H13: =G13*C13 -> 0
A14: 1085-10x10 | B14: 1085-10x10 | C14: =F14 + SUMIF(Purchase!C:C,Stock!B14,Purchase!D:D)-SUMIF(Sale!C:C,Stock!B14,Sale!D:D) -> 200 | D14: =IF(C14<E14,"Low Stock","In Stock") -> In Stock | E14: 1 | F14: 200 | G14: 0 | H14: =G14*C14 -> 0
A15: 1015-10x10 | B15: 1015-10x10 | C15: =F15 + SUMIF(Purchase!C:C,Stock!B15,Purchase!D:D)-SUMIF(Sale!C:C,Stock!B15,Sale!D:D) -> 200 | D15: =IF(C15<E15,"Low Stock","In Stock") -> In Stock | E15: 1 | F15: 200 | G15: 0 | H15: =G15*C15 -> 0
A16: 1055-10x10 | B16: 1055-10x10 | C16: =F16 + SUMIF(Purchase!C:C,Stock!B16,Purchase!D:D)-SUMIF(Sale!C:C,Stock!B16,Sale!D:D) -> 200 | D16: =IF(C16<E16,"Low Stock","In Stock") -> In Stock | E16: 1 | F16: 200 | G16: 0 | H16: =G16*C16 -> 0
... A21: 1045-10x10 | B21: 1045-10x10 | C21: =F21 + SUMIF(Purchase!C:C,Stock!B21,Purchase!D:D)-SUMIF(Sale!C:C,Stock!B21,Sale!D:D) -> 190 | D21: =IF(C21<E21,"Low Stock","In Stock") -> In Stock | E21: 1 | F21: 190 | G21: 0 | H21: =G21*C21 -> 0
A22: 1135A-8x12 | B22: 1135A-8x12 | C22: =F22 + SUMIF(Purchase!C:C,Stock!B22,Purchase!D:D)-SUMIF(Sale!C:C,Stock!B22,Sale!D:D) -> 190 | D22: =IF(C22<E22,"Low Stock","In Stock") -> In Stock | E22: 1 | F22: 190 | G22: 0 | H22: =G22*C22 -> 0 | I22: CK AGAIN
A23: 1195A-8x12 | B23: 1195A-8x12 | C23: =F23 + SUMIF(Purchase!C:C,Stock!B23,Purchase!D:D)-SUMIF(Sale!C:C,Stock!B23,Sale!D:D) -> 200 | D23: =IF(C23<E23,"Low Stock","In Stock") -> In Stock | E23: 1 | F23: 200 | G23: 0 | H23: =G23*C23 -> 0 | I23: CK AGAIN
A24: 1185A-8x12 | B24: 1185A-8x12 | C24: =F24 + SUMIF(Purchase!C:C,Stock!B24,Purchase!D:D)-SUMIF(Sale!C:C,Stock!B24,Sale!D:D) -> 200 | D24: =IF(C24<E24,"Low Stock","In Stock") -> In Stock | E24: 1 | F24: 200 | G24: 0 | H24: =G24*C24 -> 0 | I24: CK AGAIN
A25: 1155A-8x12 | B25: 1155A-8x12 | C25: =F25 + SUMIF(Purchase!C:C,Stock!B25,Purchase!D:D)-SUMIF(Sale!C:C,Stock!B25,Sale!D:D) -> 210 | D25: =IF(C25<E25,"Low Stock","In Stock") -> In Stock | E25: 1 | F25: 210 | G25: 0 | H25: =G25*C25 -> 0 | I25: CK AGAIN
A26: 1154-8x12 | B26: 1154-8x12 | C26: =F26 + SUMIF(Purchase!C:C,Stock!B26,Purchase!D:D)-SUMIF(Sale!C:C,Stock!B26,Sale!D:D) -> 190 | D26: =IF(C26<E26,"Low Stock","In Stock") -> In Stock | E26: 1 | F26: 190 | G26: 0 | H26: =G26*C26 -> 0 | I26: CK AGAIN
A27: 1105A-8x12 | B27: 1105A-8x12 | C27: =F27 + SUMIF(Purchase!C:C,Stock!B27,Purchase!D:D)-SUMIF(Sale!C:C,Stock!B27,Sale!D:D) -> 210 | D27: =IF(C27<E27,"Low Stock","In Stock") -> In Stock | E27: 1 | F27: 210 | G27: 0 | H27: =G27*C27 -> 0 | I27: CK AGAIN
A28: 1175A-8x12 | B28: 1175A-8x12 | C28: =F28 + SUMIF(Purchase!C:C,Stock!B28,Purchase!D:D)-SUMIF(Sale!C:C,Stock!B28,Sale!D:D) -> 200 | D28: =IF(C28<E28,"Low Stock","In Stock") -> In Stock | E28: 1 | F28: 200 | G28: 0 | H28: =G28*C28 -> 0 | I28: CK AGAIN
A29: 1145-8x12 | B29: 1145-8x12 | C29: =F29 + SUMIF(Purchase!C:C,Stock!B29,Purchase!D:D)-SUMIF(Sale!C:C,Stock!B29,Sale!D:D) -> 200 | D29: =IF(C29<E29,"Low Stock","In Stock") -> In Stock | E29: 1 | F29: 200 | G29: 0 | H29: =G29*C29 -> 0 | I29: CK AGAIN
A30: 1125A-8x12 | B30: 1125A-8x12 | C30: =F30 + SUMIF(Purchase!C:C,Stock!B30,Purchase!D:D)-SUMIF(Sale!C:C,Stock!B30,Sale!D:D) -> 200 | D30: =IF(C30<E30,"Low Stock","In Stock") -> In Stock | E30: 1 | F30: 200 | G30: 0 | H30: =G30*C30 -> 0 | I30: CK AGAIN
A31: 1115A-8x12 | B31: 1115A-8x12 | C31: =F31 + SUMIF(Purchase!C:C,Stock!B31,Purchase!D:D)-SUMIF(Sale!C:C,Stock!B31,Sale!D:D) -> 190 | D31: =IF(C31<E31,"Low Stock","In Stock") -> In Stock | E31: 1 | F31: 190 | G31: 0 | H31: =G31*C31 -> 0 | I31: CK AGAIN
A32: 1045A-12x12 | B32: 1045A-12x12 | C32: =F32 + SUMIF(Purchase!C:C,Stock!B32,Purchase!D:D)-SUMIF(Sale!C:C,Stock!B32,Sale!D:D) -> 200 | D32: =IF(C32<E32,"Low Stock","In Stock") -> In Stock | E32: 1 | F32: 200 | G32: 0 | H32: =G32*C32 -> 0
A33: 1075A-12x12 | B33: 1075A-12x12 | C33: =F33 + SUMIF(Purchase!C:C,Stock!B33,Purchase!D:D)-SUMIF(Sale!C:C,Stock!B33,Sale!D:D) -> 200 | D33: =IF(C33<E33,"Low Stock","In Stock") -> In Stock | E33: 1 | F33: 200 | G33: 0 | H33: =G33*C33 -> 0
A34: 1015A-12x12 | B34: 1015A-12x12 | C34: =F34 + SUMIF(Purchase!C:C,Stock!B34,Purchase!D:D)-SUMIF(Sale!C:C,Stock!B34,Sale!D:D) -> 200 | D34: =IF(C34<E34,"Low Stock","In Stock") -> In Stock | E34: 1 | F34: 200 | G34: 0 | H34: =G34*C34 -> 0
A35: 1005A-12x12 | B35: 1005A-12x12 | C35: =F35 + SUMIF(Purchase!C:C,Stock!B35,Purchase!D:D)-SUMIF(Sale!C:C,Stock!B35,Sale!D:D) -> 200 | D35: =IF(C35<E35,"Low Stock","In Stock") -> In Stock | E35: 1 | F35: 200 | G35: 0 | H35: =G35*C35 -> 0
A36: 1035A-12x12 | B36: 1035A-12x12 | C36: =F36 + SUMIF(Purchase!C:C,Stock!B36,Purchase!D:D)-SUMIF(Sale!C:C,Stock!B36,Sale!D:D) -> 200 | D36: =IF(C36<E36,"Low Stock","In Stock") -> In Stock | E36: 1 | F36: 200 | G36: 0 | H36: =G36*C36 -> 0
A37: CT-41-12x12 | B37: CT-41-12x12 | C37: =F37 + SUMIF(Purchase!C:C,Stock!B37,Purchase!D:D)-SUMIF(Sale!C:C,Stock!B37,Sale!D:D) -> 200 | D37: =IF(C37<E37,"Low Stock","In Stock") -> In Stock | E37: 1 | F37: 200 | G37: 0 | H37: =G37*C37 -> 0
A38: CT-42-12x12 | B38: CT-42-12x12 | C38: =F38 + SUMIF(Purchase!C:C,Stock!B38,Purchase!D:D)-SUMIF(Sale!C:C,Stock!B38,Sale!D:D) -> 150 | D38: =IF(C38<E38,"Low Stock","In Stock") -> In Stock | E38: 1 | F38: 150 | G38: 0 | H38: =G38*C38 -> 0
A39: CT-43-12x12 | B39: CT-43-12x12 | C39: =F39 + SUMIF(Purchase!C:C,Stock!B39,Purchase!D:D)-SUMIF(Sale!C:C,Stock!B39,Sale!D:D) -> 150 | D39: =IF(C39<E39,"Low Stock","In Stock") -> In Stock | E39: 1 | F39: 150 | G39: 0 | H39: =G39*C39 -> 0
A40: 1125-10x15 | B40: 1125-10x15 | C40: =F40 + SUMIF(Purchase!C:C,Stock!B40,Purchase!D:D)-SUMIF(Sale!C:C,Stock!B40,Sale!D:D) -> 150 | D40: =IF(C40<E40,"Low Stock","In Stock") -> In Stock | E40: 1 | F40: 150 | G40: 0 | H40: =G40*C40 -> 0
A41: 1195A-10x15 | B41: 1195A-10x15 | C41: =F41 + SUMIF(Purchase!C:C,Stock!B41,Purchase!D:D)-SUMIF(Sale!C:C,Stock!B41,Sale!D:D) -> 150 | D41: =IF(C41<E41,"Low Stock","In Stock") -> In Stock | E41: 1 | F41: 150 | G41: 0 | H41: =G41*C41 -> 0
A42: 1185-10x15 | B42: 1185-10x15 | C42: =F42 + SUMIF(Purchase!C:C,Stock!B42,Purchase!D:D)-SUMIF(Sale!C:C,Stock!B42,Sale!D:D) -> 150 | D42: =IF(C42<E42,"Low Stock","In Stock") -> In Stock | E42: 1 | F42: 150 | G42: 0 | H42: =G42*C42 -> 0
A43: 1115-10x15 | B43: 1115-10x15 | C43: =F43 + SUMIF(Purchase!C:C,Stock!B43,Purchase!D:D)-SUMIF(Sale!C:C,Stock!B43,Sale!D:D) -> 150 | D43: =IF(C43<E43,"Low Stock","In Stock") -> In Stock | E43: 1 | F43: 150 | G43: 0 | H43: =G43*C43 -> 0
... A117: 7045-10x15 | B117: 7045-10x15 | C117: =F117 + SUMIF(Purchase!C:C,Stock!B117,Purchase!D:D)-SUMIF(Sale!C:C,Stock!B117,Sale!D:D) -> 30 | D117: =IF(C117<E117,"Low Stock","In Stock") -> In Stock | E117: 1 | F117: 30 | G117: 0 | H117: =G117*C117 -> 0
...

Sheet Purchase
A1: Stock In
A3: Date | B3: CODE | C3: Product Name | D3: Quantity | E3: Price
C4: =VLOOKUP(B4,Stock!$A$2:$B$133,2,0) -> #N/A
C5: =VLOOKUP(B5,Stock!$A$2:$B$133,2,0) -> #N/A
C6: =VLOOKUP(B6,Stock!$A$2:$B$133,2,0) -> #N/A
C7: =VLOOKUP(B7,Stock!$A$2:$B$133,2,0) -> #N/A
C8: =VLOOKUP(B8,Stock!$A$2:$B$133,2,0) -> #N/A
C9: =VLOOKUP(B9,Stock!$A$2:$B$133,2,0) -> #N/A
C10: =VLOOKUP(B10,Stock!$A$2:$B$133,2,0) -> #N/A
C11: =VLOOKUP(B11,Stock!$A$2:$B$133,2,0) -> #N/A
C12: =VLOOKUP(B12,Stock!$A$2:$B$133,2,0) -> #N/A
C13: =VLOOKUP(B13,Stock!$A$2:$B$133,2,0) -> #N/A
C14: =VLOOKUP(B14,Stock!$A$2:$B$133,2,0) -> #N/A
C15: =VLOOKUP(B15,Stock!$A$2:$B$133,2,0) -> #N/A
... C704: =VLOOKUP(B704,Stock!$A$2:$B$133,2,0) -> #N/A

Sheet Sale
A1: Stock Out
A3: Date | B3: CODE | C3: Product Name | D3: Quantity | E3: price
C4: =VLOOKUP(B4,Stock!$A$2:$B$133,2,0) -> #N/A
C5: =VLOOKUP(B5,Stock!$A$2:$B$133,2,0) -> #N/A
C6: =VLOOKUP(B6,Stock!$A$2:$B$133,2,0) -> #N/A
C7: =VLOOKUP(B7,Stock!$A$2:$B$133,2,0) -> #N/A
C8: =VLOOKUP(B8,Stock!$A$2:$B$133,2,0) -> #N/A
C9: =VLOOKUP(B9,Stock!$A$2:$B$133,2,0) -> #N/A
C10: =VLOOKUP(B10,Stock!$A$2:$B$133,2,0) -> #N/A
C11: =VLOOKUP(B11,Stock!$A$2:$B$133,2,0) -> #N/A
C12: =VLOOKUP(B12,Stock!$A$2:$B$133,2,0) -> #N/A
C13: =VLOOKUP(B13,Stock!$A$2:$B$133,2,0) -> #N/A
C14: =VLOOKUP(B14,Stock!$A$2:$B$133,2,0) -> #N/A
C15: =VLOOKUP(B15,Stock!$A$2:$B$133,2,0) -> #N/A
... C1739: =VLOOKUP(B1739,Stock!$A$2:$B$133,2,0) -> #N/A

Sheet Sheet1
